<?xml version="1.0"?>
<robot name="diffbot" xmlns:xacro="http://ros.org/wiki/xacro">

    <!-- Base Link -->
    <link name="base_link">
        <visual>
            <geometry>
                <box size="0.5 0.4 0.2" />
            </geometry>
            <material name="blue">
                <color rgba="0.0 0.0 1.0 1.0" />
            </material>
        </visual>
        <collision>
            <geometry>
                <box size="0.5 0.4 0.2" />
            </geometry>
        </collision>
        <inertial>
            <mass value="10.0" />
            <origin xyz="0 0 0" />
            <inertia ixx="1" ixy="0" ixz="0" iyy="1" iyz="0" izz="1" />
        </inertial>
    </link>

    <!-- Left Wheel Link -->
    <link name="left_wheel_link">
        <visual>
            <geometry>
                <cylinder length="0.05" radius="0.08" />
            </geometry>
            <material name="black">
                <color rgba="0.0 0.0 0.0 1.0" />
            </material>
        </visual>
        <collision>
            <geometry>
                <cylinder length="0.05" radius="0.08" />
            </geometry>
        </collision>
        <inertial>
            <mass value="1" />
            <origin xyz="0 0 0" />
            <inertia ixx="0.01" ixy="0" ixz="0" iyy="0.01" iyz="0" izz="0.01" />
        </inertial>
    </link>

    <!-- Right Wheel Link -->
    <link name="right_wheel_link">
        <visual>
            <geometry>
                <cylinder length="0.05" radius="0.08" />
            </geometry>
            <material name="black">
                <color rgba="0.0 0.0 0.0 1.0" />
            </material>
        </visual>
        <collision>
            <geometry>
                <cylinder length="0.05" radius="0.08" />
            </geometry>
        </collision>
        <inertial>
            <mass value="1" />
            <origin xyz="0 0 0" />
            <inertia ixx="0.01" ixy="0" ixz="0" iyy="0.01" iyz="0" izz="0.01" />
        </inertial>
    </link>

    <!-- Left Wheel Joint -->
    <joint name="left_wheel_joint" type="continuous">
        <parent link="base_link" />
        <child link="left_wheel_link" />
        <origin xyz="0 0.2 0" rpy="0 0 0" />
        <axis xyz="0 0 1" />
    </joint>

    <!-- Right Wheel Joint -->
    <joint name="right_wheel_joint" type="continuous">
        <parent link="base_link" />
        <child link="right_wheel_link" />
        <origin xyz="0 -0.2 0" rpy="0 0 0" />
        <axis xyz="0 0 1" />
    </joint>

    <!-- Gazebo Plugin for Differential Drive -->
<gazebo>
  <plugin name="diff_drive_controller" filename="libgazebo_ros_diff_drive.so">
    <!-- Names of the joints -->
    <left_joint>left_wheel_joint</left_joint>
    <right_joint>right_wheel_joint</right_joint>

    <!-- Topic on which velocity commands will be received -->
    <command_topic>cmd_vel</command_topic>
    
    <!-- Publish odometry on /odom -->
    <odometry_topic>odom</odometry_topic>
    <odometry_frame>odom</odometry_frame>

    <!-- TF for odom->base_link transform -->
    <robot_base_frame>base_link</robot_base_frame>

    <!-- Wheel separation & radius (should match URDF) -->
    <wheel_separation>0.4</wheel_separation>
    <wheel_radius>0.08</wheel_radius>

    <!-- Plugin parameters -->
    <update_rate>50</update_rate>
    <publish_tf>true</publish_tf>
  </plugin>
</gazebo>

</robot>